<?xml version="1.0" encoding="utf-8"?>
<!-- This URDF was automatically created by SolidWorks to URDF Exporter! Originally created by Stephen Brawner (brawner@gmail.com) 
     Commit Version: 1.6.0-4-g7f85cfe  Build Version: 1.6.7995.38578
     For more information, please see http://wiki.ros.org/sw_urdf_exporter -->
<robot
  name="2wheels">
  <link
    name="base_link">
    <inertial>
      <origin
        xyz="2.77555756156289E-17 3.6350904874527E-06 0.159731755653893"
        rpy="0 0 0" />
      <mass
        value="7.26144947250641" />
      <inertia
        ixx="0.241534655163857"
        ixy="2.75404202185237E-17"
        ixz="1.30432869443467E-17"
        iyy="0.149829158736982"
        iyz="4.8205065674273E-06"
        izz="0.207402617250907" />
    </inertial>
    <visual>
      <origin
        xyz="0 0 0"
        rpy="0 0 0" />
      <geometry>
        <mesh
          filename="package://2wheels/meshes/base_link.STL" />
      </geometry>
      <material
        name="">
        <color
          rgba="0.792156862745098 0.819607843137255 0.933333333333333 1" />
      </material>
    </visual>
    <collision>
      <origin
        xyz="0 0 0"
        rpy="0 0 0" />
      <geometry>
        <mesh
          filename="package://2wheels/meshes/base_link.STL" />
      </geometry>
    </collision>
  </link>
  <link
    name="left_wheel_link">
    <inertial>
      <origin
        xyz="5.3702E-07 -0.52449 -3.1189E-08"
        rpy="0 0 0" />
      <mass
        value="2.95" />
      <inertia
        ixx="1.8743E-06"
        ixy="-9.9049E-14"
        ixz="-3.6547E-11"
        iyy="3.2601E-06"
        iyz="1.4479E-12"
        izz="1.8748E-06" />
    </inertial>
    <visual>
      <origin
        xyz="0 0 0"
        rpy="0 0 0" />
      <geometry>
        <mesh
          filename="package://2wheels/meshes/left_wheel_Link.STL" 
        />
      </geometry>
      <material
        name="">
        <color
          rgba="0.49804 0.49804 0.49804 1" />
      </material>
    </visual>
    <collision>
      <origin
        xyz="0 0 0"
        rpy="1.57 0 0" />
      <geometry>
          <cylinder radius="0.085" length="0.041"/>
      </geometry>
    </collision>
  </link>
  <joint
    name="left_wheel_joint"
    type="continuous">
    <origin
      xyz="0 -0.2625 0"
      rpy="0 0 0" />
    <parent
      link="base_link" />
    <child
      link="left_wheel_link" />
    <axis
      xyz="0 1 0" />
    <limit
      effort="12"
      velocity="7.27" />
  </joint>
  <gazebo reference="left_wheel_link">
    <kp>1000000.0</kp>
    <kd>1000.0</kd>
    <mu1>1.0</mu1>
    <mu2>0.1</mu2>
    <fdir1>1 0 0</fdir1>
    <maxVel>1.0</maxVel>
    <minDepth>0.00</minDepth>
    <implicitSpringDamper>1</implicitSpringDamper>
    <material>Gazebo/Grey</material>
  </gazebo>
  <link
    name="right_wheel_link">
    <inertial>
      <origin
        xyz="5.3202E-07 -0.0005133 7.9509E-08"
        rpy="0 0 0" />
      <mass
        value="2.95" />
      <inertia
        ixx="1.8743E-06"
        ixy="-3.1976E-14"
        ixz="-1.1652E-11"
        iyy="3.2601E-06"
        iyz="1.4509E-12"
        izz="1.8748E-06" />
    </inertial>
    <visual>
      <origin
        xyz="0 0 0"
        rpy="0 0 0" />
      <geometry>
        <mesh
          filename="package://2wheels/meshes/right_wheel_Link.STL" />
      </geometry>
      <material
        name="">
        <color
          rgba="0.49804 0.49804 0.49804 1" />
      </material>
    </visual>
    <collision>
      <origin
        xyz="0 0 0"
        rpy="1.57 0 0" />
      <geometry>
        <cylinder radius="0.085" length="0.041"/>
      </geometry>
    </collision>
  </link>
  <joint
    name="right_wheel_joint"
    type="continuous">
    <origin
      xyz="0 0.2625 0"
      rpy="0 0 0" />
    <parent
      link="base_link" />
    <child
      link="right_wheel_link" />
    <axis
      xyz="0 1 0" />
    <limit
      effort="12"
      velocity="7.27" />
  </joint>
  <gazebo reference="right_wheel_link">
    <kp>1000000.0</kp>
    <kd>1000.0</kd>
    <mu1>1.0</mu1>
    <mu2>0.1</mu2>
    <fdir1>1 0 0</fdir1>
    <maxVel>1.0</maxVel>
    <minDepth>0.00</minDepth>
    <implicitSpringDamper>1</implicitSpringDamper>
    <material>Gazebo/Grey</material>
  </gazebo>
  <ros2_control name="selfbalancerobot_system" type="system">
    <hardware>
      <plugin>gz_ros2_control/GazeboSimSystem</plugin>
    </hardware>
    <joint name="right_wheel_joint">
      <command_interface name="velocity">
        <param name="min">-7.27</param>
        <param name="max">7.27</param>
      </command_interface>
      <command_interface name="effort">
        <param name="min">-12</param>
        <param name="max">12</param>
      </command_interface>
      <state_interface name="position"/>
      <state_interface name="velocity"/>
      <state_interface name="effort"/>
    </joint>
    <joint name="left_wheel_joint">
      <command_interface name="velocity">
        <param name="min">-7.27</param>
        <param name="max">7.27</param>
      </command_interface>
      <command_interface name="effort">
        <param name="min">-12</param>
        <param name="max">12</param>
      </command_interface>
      <state_interface name="position"/>
      <state_interface name="velocity"/>
      <state_interface name="effort"/>
    </joint>
  </ros2_control>
  <link name="base_imu_link">
    <inertial>
      <mass value="0.01"/>
      <origin xyz="0 0 0"/>
      <inertia ixx="0.000001" ixy="0" ixz="0" iyy="0.000001" iyz="0" izz="0.000001"/>
    </inertial>
  </link>
  <joint name="base_imu_joint" type="fixed">
    <parent link="base_link"/>
    <child link="base_imu_link"/>
    <origin rpy="0 0 0" xyz="0 0 0"/>
  </joint>
  <gazebo reference="base_imu_link">
    <sensor name="base_imu_sensor" type="imu">
      <always_on>1</always_on>
      <update_rate>100.0</update_rate>
      <visualize>true</visualize>
      <topic>base_imu</topic>
      <gz_frame_id>base_imu_link</gz_frame_id>
    </sensor>
  </gazebo>
  <gazebo>
    <plugin filename="libgz_ros2_control-system.so"
            name="gz_ros2_control::GazeboSimROS2ControlPlugin">
      <parameters>/home/nahhao74/Robot_sim_ws/install/2wheels/share/2wheels/config/controller.yaml</parameters>
    </plugin>
    <plugin
      filename="gz-sim-imu-system"
      name="gz::sim::systems::Imu">
    </plugin>
  </gazebo>

</robot>

